2025-03-10 00:05:14,472 INFO    Thread-103 (_run_job):140707 [wandb_setup.py:_flush():67] Current SDK version is 0.19.7
2025-03-10 00:05:14,472 INFO    Thread-103 (_run_job):140707 [wandb_setup.py:_flush():67] Configure stats pid to 140707
2025-03-10 00:05:14,472 INFO    Thread-103 (_run_job):140707 [wandb_setup.py:_flush():67] Loading settings from /home/snehal/.config/wandb/settings
2025-03-10 00:05:14,472 INFO    Thread-103 (_run_job):140707 [wandb_setup.py:_flush():67] Loading settings from /home/snehal/Downloads/dl_ass1/wandb/settings
2025-03-10 00:05:14,472 INFO    Thread-103 (_run_job):140707 [wandb_setup.py:_flush():67] Loading settings from environment variables
2025-03-10 00:05:14,472 INFO    Thread-103 (_run_job):140707 [wandb_init.py:setup_run_log_directory():647] Logging user logs to /home/snehal/Downloads/dl_ass1/wandb/run-20250310_000514-rtya0wcl/logs/debug.log
2025-03-10 00:05:14,472 INFO    Thread-103 (_run_job):140707 [wandb_init.py:setup_run_log_directory():648] Logging internal logs to /home/snehal/Downloads/dl_ass1/wandb/run-20250310_000514-rtya0wcl/logs/debug-internal.log
2025-03-10 00:05:14,472 INFO    Thread-103 (_run_job):140707 [wandb_init.py:monkeypatch_ipython():599] configuring jupyter hooks <wandb.sdk.wandb_init._WandbInit object at 0x7b5ffc5dae10>
2025-03-10 00:05:14,473 INFO    Thread-103 (_run_job):140707 [wandb_init.py:init():761] calling init triggers
2025-03-10 00:05:14,473 INFO    Thread-103 (_run_job):140707 [wandb_init.py:init():766] wandb.init called with sweep_config: {'activation_function': 'relu', 'batch_size': 16, 'epochs': 15, 'hidden_layer_size': 128, 'learning_rate': 0.0001, 'num_hidden_layers': 4, 'optimizer': 'nadam', 'weight_decay': 0.5, 'weight_init': 'xavier'}
config: {'_wandb': {}}
2025-03-10 00:05:14,473 INFO    Thread-103 (_run_job):140707 [wandb_init.py:init():784] starting backend
2025-03-10 00:05:14,473 INFO    Thread-103 (_run_job):140707 [wandb_init.py:init():788] sending inform_init request
2025-03-10 00:05:14,475 INFO    Thread-103 (_run_job):140707 [backend.py:_multiprocessing_setup():97] multiprocessing start_methods=fork,spawn,forkserver, using: spawn
2025-03-10 00:05:14,475 INFO    Thread-103 (_run_job):140707 [wandb_init.py:init():803] backend started and connected
2025-03-10 00:05:14,477 INFO    Thread-103 (_run_job):140707 [wandb_run.py:_config_callback():1261] config_cb None None {'activation_function': 'relu', 'batch_size': 16, 'epochs': 15, 'hidden_layer_size': 128, 'learning_rate': 0.0001, 'num_hidden_layers': 4, 'optimizer': 'nadam', 'weight_decay': 0.5, 'weight_init': 'xavier'}
2025-03-10 00:05:14,480 INFO    Thread-103 (_run_job):140707 [wandb_run.py:_label_probe_notebook():1204] probe notebook
2025-03-10 00:05:14,500 INFO    Thread-103 (_run_job):140707 [wandb_init.py:init():896] updated telemetry
2025-03-10 00:05:14,511 INFO    Thread-103 (_run_job):140707 [wandb_init.py:init():920] communicating run to backend with 90.0 second timeout
2025-03-10 00:05:14,966 INFO    Thread-103 (_run_job):140707 [wandb_init.py:init():995] starting run threads in backend
2025-03-10 00:05:15,105 INFO    Thread-103 (_run_job):140707 [wandb_run.py:_console_start():2377] atexit reg
2025-03-10 00:05:15,106 INFO    Thread-103 (_run_job):140707 [wandb_run.py:_redirect():2227] redirect: wrap_raw
2025-03-10 00:05:15,106 INFO    Thread-103 (_run_job):140707 [wandb_run.py:_redirect():2292] Wrapping output streams.
2025-03-10 00:05:15,106 INFO    Thread-103 (_run_job):140707 [wandb_run.py:_redirect():2317] Redirects installed.
2025-03-10 00:05:15,107 INFO    Thread-103 (_run_job):140707 [wandb_init.py:init():1037] run started, returning control to user process
2025-03-10 00:20:36,603 INFO    Thread-103 (_run_job):140707 [wandb_run.py:_finish():2112] finishing run snehalma23m020-iit-madras/DLassignment1/rtya0wcl
2025-03-10 00:20:36,603 ERROR   Thread-103 (_run_job):140707 [jupyter.py:save_history():450] Run pip install nbformat to save notebook history
2025-03-10 00:20:36,603 INFO    Thread-103 (_run_job):140707 [jupyter.py:save_ipynb():386] not saving jupyter notebook
2025-03-10 00:20:36,603 INFO    Thread-103 (_run_job):140707 [wandb_init.py:_jupyter_teardown():581] cleaning up jupyter logic
2025-03-10 00:20:36,603 INFO    Thread-103 (_run_job):140707 [wandb_run.py:_atexit_cleanup():2342] got exitcode: 0
2025-03-10 00:20:36,603 INFO    Thread-103 (_run_job):140707 [wandb_run.py:_restore():2324] restore
2025-03-10 00:20:36,603 INFO    Thread-103 (_run_job):140707 [wandb_run.py:_restore():2330] restore done
2025-03-10 00:24:02,661 INFO    Thread-15 (_heartbeat):140707 [retry.py:__call__():175] Retry attempt failed:
Traceback (most recent call last):
  File "/home/snehal/Downloads/dl_ass1/dvenv/lib/python3.12/site-packages/urllib3/connection.py", line 198, in _new_conn
    sock = connection.create_connection(
           ^^^^^^^^^^^^^^^^^^^^^^^^^^^^^
  File "/home/snehal/Downloads/dl_ass1/dvenv/lib/python3.12/site-packages/urllib3/util/connection.py", line 60, in create_connection
    for res in socket.getaddrinfo(host, port, family, socket.SOCK_STREAM):
               ^^^^^^^^^^^^^^^^^^^^^^^^^^^^^^^^^^^^^^^^^^^^^^^^^^^^^^^^^^
  File "/usr/lib/python3.12/socket.py", line 963, in getaddrinfo
    for res in _socket.getaddrinfo(host, port, family, type, proto, flags):
               ^^^^^^^^^^^^^^^^^^^^^^^^^^^^^^^^^^^^^^^^^^^^^^^^^^^^^^^^^^^
socket.gaierror: [Errno -2] Name or service not known

The above exception was the direct cause of the following exception:

Traceback (most recent call last):
  File "/home/snehal/Downloads/dl_ass1/dvenv/lib/python3.12/site-packages/urllib3/connectionpool.py", line 787, in urlopen
    response = self._make_request(
               ^^^^^^^^^^^^^^^^^^^
  File "/home/snehal/Downloads/dl_ass1/dvenv/lib/python3.12/site-packages/urllib3/connectionpool.py", line 488, in _make_request
    raise new_e
  File "/home/snehal/Downloads/dl_ass1/dvenv/lib/python3.12/site-packages/urllib3/connectionpool.py", line 464, in _make_request
    self._validate_conn(conn)
  File "/home/snehal/Downloads/dl_ass1/dvenv/lib/python3.12/site-packages/urllib3/connectionpool.py", line 1093, in _validate_conn
    conn.connect()
  File "/home/snehal/Downloads/dl_ass1/dvenv/lib/python3.12/site-packages/urllib3/connection.py", line 704, in connect
    self.sock = sock = self._new_conn()
                       ^^^^^^^^^^^^^^^^
  File "/home/snehal/Downloads/dl_ass1/dvenv/lib/python3.12/site-packages/urllib3/connection.py", line 205, in _new_conn
    raise NameResolutionError(self.host, self, e) from e
urllib3.exceptions.NameResolutionError: <urllib3.connection.HTTPSConnection object at 0x7b5ff9d6e9c0>: Failed to resolve 'api.wandb.ai' ([Errno -2] Name or service not known)

The above exception was the direct cause of the following exception:

Traceback (most recent call last):
  File "/home/snehal/Downloads/dl_ass1/dvenv/lib/python3.12/site-packages/requests/adapters.py", line 667, in send
    resp = conn.urlopen(
           ^^^^^^^^^^^^^
  File "/home/snehal/Downloads/dl_ass1/dvenv/lib/python3.12/site-packages/urllib3/connectionpool.py", line 841, in urlopen
    retries = retries.increment(
              ^^^^^^^^^^^^^^^^^^
  File "/home/snehal/Downloads/dl_ass1/dvenv/lib/python3.12/site-packages/urllib3/util/retry.py", line 519, in increment
    raise MaxRetryError(_pool, url, reason) from reason  # type: ignore[arg-type]
    ^^^^^^^^^^^^^^^^^^^^^^^^^^^^^^^^^^^^^^^^^^^^^^^^^^^
urllib3.exceptions.MaxRetryError: HTTPSConnectionPool(host='api.wandb.ai', port=443): Max retries exceeded with url: /graphql (Caused by NameResolutionError("<urllib3.connection.HTTPSConnection object at 0x7b5ff9d6e9c0>: Failed to resolve 'api.wandb.ai' ([Errno -2] Name or service not known)"))

During handling of the above exception, another exception occurred:

Traceback (most recent call last):
  File "/home/snehal/Downloads/dl_ass1/dvenv/lib/python3.12/site-packages/wandb/sdk/lib/retry.py", line 134, in __call__
    result = self._call_fn(*args, **kwargs)
             ^^^^^^^^^^^^^^^^^^^^^^^^^^^^^^
  File "/home/snehal/Downloads/dl_ass1/dvenv/lib/python3.12/site-packages/wandb/sdk/internal/internal_api.py", line 398, in execute
    return self.client.execute(*args, **kwargs)  # type: ignore
           ^^^^^^^^^^^^^^^^^^^^^^^^^^^^^^^^^^^^
  File "/home/snehal/Downloads/dl_ass1/dvenv/lib/python3.12/site-packages/wandb/vendor/gql-0.2.0/wandb_gql/client.py", line 52, in execute
    result = self._get_result(document, *args, **kwargs)
             ^^^^^^^^^^^^^^^^^^^^^^^^^^^^^^^^^^^^^^^^^^^
  File "/home/snehal/Downloads/dl_ass1/dvenv/lib/python3.12/site-packages/wandb/vendor/gql-0.2.0/wandb_gql/client.py", line 60, in _get_result
    return self.transport.execute(document, *args, **kwargs)
           ^^^^^^^^^^^^^^^^^^^^^^^^^^^^^^^^^^^^^^^^^^^^^^^^^
  File "/home/snehal/Downloads/dl_ass1/dvenv/lib/python3.12/site-packages/wandb/sdk/lib/gql_request.py", line 58, in execute
    request = self.session.post(self.url, **post_args)
              ^^^^^^^^^^^^^^^^^^^^^^^^^^^^^^^^^^^^^^^^
  File "/home/snehal/Downloads/dl_ass1/dvenv/lib/python3.12/site-packages/requests/sessions.py", line 637, in post
    return self.request("POST", url, data=data, json=json, **kwargs)
           ^^^^^^^^^^^^^^^^^^^^^^^^^^^^^^^^^^^^^^^^^^^^^^^^^^^^^^^^^
  File "/home/snehal/Downloads/dl_ass1/dvenv/lib/python3.12/site-packages/requests/sessions.py", line 589, in request
    resp = self.send(prep, **send_kwargs)
           ^^^^^^^^^^^^^^^^^^^^^^^^^^^^^^
  File "/home/snehal/Downloads/dl_ass1/dvenv/lib/python3.12/site-packages/requests/sessions.py", line 703, in send
    r = adapter.send(request, **kwargs)
        ^^^^^^^^^^^^^^^^^^^^^^^^^^^^^^^
  File "/home/snehal/Downloads/dl_ass1/dvenv/lib/python3.12/site-packages/requests/adapters.py", line 700, in send
    raise ConnectionError(e, request=request)
requests.exceptions.ConnectionError: HTTPSConnectionPool(host='api.wandb.ai', port=443): Max retries exceeded with url: /graphql (Caused by NameResolutionError("<urllib3.connection.HTTPSConnection object at 0x7b5ff9d6e9c0>: Failed to resolve 'api.wandb.ai' ([Errno -2] Name or service not known)"))
2025-03-10 00:30:06,190 INFO    MsgRouterThr:140707 [mailbox.py:close():115] Closing mailbox, abandoning 1 handles.
2025-03-10 00:30:06,192 INFO    Thread-103 (_run_job):140707 [wandb_run.py:_footer_history_summary_info():3958] rendering history
2025-03-10 00:30:06,193 INFO    Thread-103 (_run_job):140707 [wandb_run.py:_footer_history_summary_info():3990] rendering summary
2025-03-10 00:30:06,195 INFO    Thread-103 (_run_job):140707 [wandb_run.py:_footer_sync_info():3919] logging synced files
